Workbook

Sheet SET 01
A1: Slot | B1: Slug | C1: Statut | D1: Faction | E1: Rareté | F1: Type | G1: Coût | H1: ATQ | I1: INT | J1: CELL | K1: Effet | L1: Synchro (coût) | M1: Synchro (effet) | N1: Flavor | O1: Full art | P1: Zone | Q1: Rôle | R1: Fichier attendu | S1: Prompt Midjourney
A2: R01 | B2: recrue-du-cycle | C2: Forgée | D2: RIKKEN | E2: Standard | F2: Traveler | G2: 1 | H2: 1 | I2: 2 | J2: Combinaison pré-CELL | N2: Le test peut la tuer. Elle a signé quand même. | O2: Non | P2: — | Q2: early drop | R2: recrue-du-cycle.png | S2: young female recruit in a matte black training bodysuit vaulting over an obstacle wall, morning light shafts through high skylights, dust motes, instructors watching from a gantry, blue and amber training lights, league of legends splash art, highly detailed, dynamic composition, cinematic lighting --no fantasy armor, text, watermark
A3: R02 | B3: technicienne-de-la-centrale | C3: Forgée | D3: RIKKEN | E3: Standard | F3: Traveler | G3: 2 | H3: 1 | I3: 3 | J3: Personnel de la Centrale | K3: À l'arrivée : restaurez 2 Intégrité à une unité alliée. | N3: Huit cents mètres sous Odaiba, quelqu'un doit bien serrer les boulons. | O3: Non | P3: — | Q3: soigneur early | R3: technicienne-de-la-centrale.png | S3: female engineer in dark work uniform riding an open elevator platform down a colossal glowing core shaft, hair blown upward, wrench on her shoulder, blue-white light rising from far below, amber safety beacons flashing past, league of legends splash art, highly detailed, dynamic composition, cinematic lighting --no fantasy armor, text, watermark
A4: R03 | B4: operationnelle-cell-aqua | C4: Forgée | D4: RIKKEN | E4: Standard | F4: Traveler | G4: 2 | H4: 2 | I4: 2 | J4: CELL Aqua | L4: 1 | M4: Hydro-blindage : +0/+2. | N4: L'eau ne force pas. Elle trouve le chemin. | O4: Non | P4: — | Q4: synchro cheap | R4: operationnelle-cell-aqua.png | S4: female operative in a matte black segmented exosuit walking out of the sea at dawn, ribbons of water spiraling off her cyan-lit conduits, wet sand mirroring the pink sky, league of legends splash art, highly detailed, dynamic composition, cinematic lighting --no fantasy armor, medieval knight armor, text, watermark
A5: R04 | B5: eclaireuse-temporelle | C5: Forgée | D5: RIKKEN | E5: Standard | F5: Traveler | G5: 3 | H5: 2 | I5: 3 | J5: CELL de série · Course | K5: Célérité. | N5: Arrivée avant le rapport qui l'annonçait. | O5: Oui | P5: Z-01 | Q5: tempo (Célérité) | R5: eclaireuse-temporelle.png | S5: female scout in a matte black segmented exosuit leaping between wooden scaffolding beams above the rooftops of 1888 paris at sunrise, blue suit seams trailing, sea of fog below, golden light on iron beams, league of legends splash art, highly detailed, dynamic composition, cinematic lighting --no eiffel tower, fantasy armor, text, watermark
A6: R05 | B6: garde-de-plateforme | C6: Forgée | D6: RIKKEN | E6: Standard | F6: Traveler | G6: 3 | H6: 2 | I6: 4 | J6: CELL de série · Rempart | K6: Garde. | N6: Personne ne passe. La question ne s'est jamais posée. | O6: Non | P6: — | Q6: mur early (Garde) | R6: garde-de-plateforme.png | S6: massive guard in a heavy matte black exosuit bracing wide-stance against a shockwave of blue light from an activating transfer platform, sparks streaming past him, his scarred face gritted and lit blue, amber alarms spinning, league of legends splash art, highly detailed, dynamic composition, cinematic lighting --no fantasy armor, giant robot, full helmet, text, watermark
A7: R06 | B7: analyste-du-drft | C7: Forgée | D7: RIKKEN | E7: Standard | F7: Traveler | G7: 4 | H7: 3 | I7: 3 | J7: Personnel du DRFT | K7: À l'arrivée : piochez une carte. | N7: Il a lu votre dossier. Il a lu tous les dossiers. | O7: Non | P7: — | Q7: pioche | R7: analyste-du-drft.png | S7: stern analyst with round glasses striding down a bright white archive hall, an armful of dossiers, loose pages flying behind him, holographic candidate faces flickering along the walls, cold daylight with one red rejected stamp, league of legends splash art, highly detailed, dynamic composition, cinematic lighting --no fantasy armor, text, watermark
A8: R07 | B8: rappel-a-la-centrale | C8: Forgée | D8: RIKKEN | E8: Standard | F8: Protocole | G8: 2 | K8: Renvoyez une unité alliée dans votre main. Votre Centrale restaure 3 Intégrité. | N8: Le retour est toujours plus doux que le départ. | O8: Non | P8: — | Q8: soin / retour | R8: rappel-a-la-centrale.png | S8: a runner dissolving into ascending blue-white light streaks mid-stride on a busy 2049 tokyo crosswalk in daylight, pedestrians turning in shock, his coffee cup suspended mid-air, league of legends splash art, highly detailed, dynamic composition, cinematic lighting --no fantasy magic, text, watermark
A9: R08 | B9: briefing-de-mission | C9: Forgée | D9: RIKKEN | E9: Standard | F9: Protocole | G9: 3 | K9: Piochez 2 cartes. | N9: Toutes les époques sur une table. Choisissez votre siècle. | O9: Non | P9: — | Q9: pioche | R9: briefing-de-mission.png | S9: top-down view of officers standing on a glass floor above a huge rotating holographic map of seven historical eras, one era glowing blank and white, coffee cups and files scattered on the glass, blue glow lighting them from below, league of legends splash art, highly detailed, cinematic lighting --no fantasy magic, text, watermark
A10: R09 | B10: mariam-diallo | C10: Forgée | D10: RIKKEN | E10: Rare | F10: Traveler | G10: 3 | H10: 2 | I10: 4 | J10: CELL Caduceus | L10: 1 | M10: Nano-fluide : restaurez 4 Intégrité à une unité alliée. | N10: Sauver autrui la vide. Elle recommence quand même. | O10: Non | P10: — | Q10: soigneuse | R10: mariam-diallo.png | S10: young franco-senegalese medic in a matte black segmented exosuit running through warm rain carrying a wounded soldier on her back, her palm glowing cyan against his chest, field camp lanterns smearing in the wet dusk, league of legends splash art, highly detailed, dynamic composition, cinematic lighting --no fantasy armor, text, watermark
A11: R10 | B11: aiko-sakuraba | C11: Forgée | D11: RIKKEN | E11: Rare | F11: Traveler | G11: 2 | H11: 1 | I11: 3 | J11: CELL Stratos | L11: 1 | M11: Analyse : regardez les 3 prochaines cartes de votre deck, piochez-en une. | N11: L'analyse reste probabiliste. C'est ce qui la ronge. | O11: Non | P11: — | Q11: valeur / info | R11: aiko-sakuraba.png | S11: young japanese woman in a matte black segmented exosuit standing on the top beam of a radio tower at dawn, wind whipping her hair, HUD visor streaming blue data against the pale gold sky, clouds far below, league of legends splash art, highly detailed, cinematic lighting --no fantasy armor, text, watermark
A12: R11 | B12: porteur-cell-pyros | C12: Forgée | D12: RIKKEN | E12: Rare | F12: Traveler | G12: 4 | H12: 4 | I12: 4 | J12: CELL Pyros | L12: 2 | M12: Surchauffe : infligez 3 dégâts à une unité. | N12: Le feu ne le brûle plus. C'est tout le reste qui brûle. | O12: Non | P12: — | Q12: Synchro dégâts | R12: porteur-cell-pyros.png | S12: male traveler in a clearly visible matte black segmented exosuit with glowing ember channels, diving between new york style skyscrapers, flames streaming from his forearms and shoulders like a fiery wake behind him, his armor plates crisp and unobscured against the fire, fist cocked mid-strike, shattered glass glittering, cool blue city dusk against the blazing orange, league of legends splash art, highly detailed, dynamic composition, cinematic lighting --no fantasy armor, body fully engulfed in fire, text, watermark
A13: R12 | B13: senior-descorte | C13: Forgée | D13: RIKKEN | E13: Rare | F13: Traveler | G13: 5 | H13: 3 | I13: 6 | J13: CELL de série · Bastion | K13: Garde. | N13: Trois cycles de recrues lui ont survécu. C'est le but. | O13: Non | P13: — | Q13: mur milieu (Garde) | R13: senior-descorte.png | S13: grey-templed veteran in a scarred matte black exosuit bracing his shoulder against a buckling steel door, impact flare blooming through the gap, debris flying past him, his blue seams flickering under the strain, league of legends splash art, highly detailed, dynamic composition, cinematic lighting --no fantasy armor, text, watermark
A14: R13 | B14: transfert-durgence | C14: Forgée | D14: RIKKEN | E14: Rare | F14: Protocole | G14: 2 | K14: Renvoyez un Traveler allié dans votre main. Son prochain Transfert coûte (1) de moins. | N14: La Centrale n'aime pas les retours imprévus. Elle les autorise quand même. | O14: Non | P14: — | Q14: flexibilité | R14: transfert-durgence.png | S14: a man in civilian clothes yanked off his feet toward a blazing blue-white light column, one arm dissolving into particles, terrified eyes meeting the viewer, morning light through tall lab windows, red alerts blinking, league of legends splash art, highly detailed, dynamic composition, cinematic lighting --no fantasy magic, text, watermark
A15: R14 | B15: bouclier-de-plateforme | C15: Forgée | D15: RIKKEN | E15: Rare | F15: Protocole | G15: 3 | K15: Vos unités gagnent +0/+2. | N15: Le dôme tient tant que la Centrale respire. | O15: Non | P15: — | Q15: protection | R15: bouclier-de-plateforme.png | S15: squad of travelers in matte black exosuits kneeling under a translucent blue energy dome in a raging desert sandstorm, ancient arrows and debris shattering against the shield in amber bursts, league of legends splash art, highly detailed, dynamic composition, cinematic lighting --no fantasy armor, creatures, text, watermark
A16: R15 | B16: coordinatrice-descouade | C16: Forgée | D16: RIKKEN | E16: Épique | F16: Traveler | G16: 4 | H16: 3 | I16: 4 | J16: CELL de série · Relais | K16: Vos Synchros coûtent (1) de moins. | N16: Trois équipes, trois siècles, une seule voix dans l'oreillette. | O16: Non | P16: — | Q16: synergie Synchro | R16: coordinatrice-descouade.png | S16: female coordinator in dark officer uniform leaning over the rail of a floating gantry, pointing sharply, a ring of giant mission screens glowing around her showing three different eras, blue light from below and amber comm lights, league of legends splash art, highly detailed, cinematic lighting --no fantasy armor, text, watermark
A17: R16 | B17: viktor-volkov | C17: Forgée | D17: RIKKEN | E17: Épique | F17: Traveler | G17: 3 | H17: 3 | I17: 2 | J17: CELL Phaeton | K17: Célérité. | L17: 1 | M17: Nitro : +2 Attaque jusqu'à la fin du tour. | N17: Il agit. Il pense après. Dans cet ordre-là, toujours. | O17: Non | P17: — | Q17: tempo burst | R17: viktor-volkov.png | S17: young russian traveler grinning mid-leap high between two rooftops, orange nitro flames roaring from his calf conduits, 2049 tokyo spread far below in teal evening haze, his silhouette against the blazing sunset, league of legends splash art, highly detailed, dynamic composition, cinematic lighting --no fantasy armor, text, watermark
A18: R17 | B18: porteur-cell-magnus | C18: Forgée | D18: RIKKEN | E18: Épique | F18: Traveler | G18: 6 | H18: 5 | I18: 6 | J18: CELL Magnus | L18: 2 | M18: Magnétosphère : vos autres Travelers gagnent +1/+1. | N18: Le fer se souvient de lui. | O18: Non | P18: — | Q18: finisher collectif | R18: porteur-cell-magnus.png | S18: traveler in a matte black segmented exosuit walking slowly across a cratered ancient battlefield as thousands of rusted blades and iron shards rise from the mud around him like reversed rain, bronze fog, his blue seams the only cold light, league of legends splash art, highly detailed, cinematic lighting --no fantasy armor, fantasy magic, text, watermark
A19: R18 | B19: allocation-denergie | C19: Forgée | D19: RIKKEN | E19: Épique | F19: Protocole | G19: 4 | K19: Ce tour-ci, vos Synchros coûtent (0). | N19: La Centrale a hurlé six secondes. Toutes les équipes s'en souviennent. | O19: Non | P19: — | Q19: swing | R19: allocation-denergie.png | S19: vertical view up the throat of a colossal energy core mid-overload, rings of machinery blazing blue-white, engineers zip-lining away on cables, steam and amber strobes, industrial cathedral scale, league of legends splash art, highly detailed, dynamic composition, cinematic lighting --no spaceship, explosion, text, watermark
A20: R19 | B20: yuriko-watanabe | C20: À générer | D20: RIKKEN | E20: Légendaire | F20: Traveler | G20: 5 | O20: Oui | P20: — | Q20: moteur de pioche | R20: yuriko-watanabe.png | S20: stern japanese woman in an impeccable dark uniform standing in a vast white amphitheater as hundreds of holographic candidate portraits flicker out around her, only three still lit, her red pen paused over a list, cold daylight, league of legends splash art, highly detailed, cinematic lighting --no fantasy armor, text, watermark
A21: R20 | B21: genjiro-hayashi | C21: Forgée | D21: RIKKEN | E21: Légendaire | F21: Traveler | G21: 6 | H21: 4 | I21: 7 | J21: Proto-CELL · 2000 | K21: Garde. | L21: 2 | M21: Onde percussive : inflige 2 dégâts à toutes les unités ennemies. | N21: Sa puissance use son passé. Il paye ses années sans discuter. | O21: Oui | P21: — | Q21: tank AoE (Garde) | R21: genjiro-hayashi.png | S21: huge japanese man in his sixties charging through a collapsing wall in a first-generation exosuit of patinated copper and brass, steam pistons venting, rubble bouncing off his shoulders, warm brass light through the dust, league of legends splash art, highly detailed, dynamic composition, cinematic lighting --no medieval knight armor, fantasy armor, text, watermark
A22: R21 | B22: liang-chen | C22: À générer | D22: RIKKEN | E22: Légendaire | F22: Traveler | G22: 7 | O22: Oui | P22: — | Q22: top curve | R22: liang-chen.png | S22: broad-shouldered chinese man in a heavy matte black exosuit frozen at the instant his fist meets a flooded arena floor, a crown of water erupting around the impact, shockwave rings in the shallow water, floodlights refracting through the spray, league of legends splash art, highly detailed, dynamic composition, cinematic lighting --no fantasy armor, hulk, text, watermark
A23: R22 | B23: hugo-tachibana | C23: Forgée | D23: RIKKEN | E23: Prismatique | F23: Traveler | G23: 4 | H23: 3 | I23: 5 | J23: CELL-T | K23: À l'arrivée : piochez une carte si vous contrôlez un autre Traveler. | L23: 2 | M23: Copiez l'effet de Synchro d'un autre Traveler allié synchronisé. | N23: Ce que le suit absorbe, c'est ce que l'équipe lui apporte. | O23: Oui | P23: Z-07 | Q23: signature (Synthèse) | R23: hugo-tachibana.png | S23: 19 year old french-japanese young man with light beige hair and one red strand falling backward through a shattering sky of seven eras, fragments showing paris scaffolds, snowy trenches, feudal bridges and ice seas, his prototype exosuit syncing with multi-hued light, calm eyes reaching upward, golden circle glowing on his chest, league of legends splash art, highly detailed, dynamic composition, cinematic lighting --no fantasy armor, text, watermark
A24: K01 | B24: agent-kairos | C24: Forgée | D24: KAIROS | E24: Standard | F24: Traveler | G24: 2 | H24: 2 | I24: 3 | J24: Sans CELL déclaré | K24: À l'arrivée : regardez la main de votre adversaire. | N24: Son badge RIKKEN est authentique. C'est bien le problème. | O24: Non | P24: — | Q24: info early | R24: agent-kairos.png | S24: unremarkable agent in RIKKEN staff uniform walking through a crowded bright lobby, every other person motion-blurred, his badge catching a tiny red glint, cold daylight through glass, league of legends splash art, highly detailed, cinematic lighting --no fantasy armor, text, watermark
A25: K02 | B25: taupe-du-recrutement | C25: À générer | D25: KAIROS | E25: Standard | F25: Traveler | G25: 1 | O25: Non | P25: — | Q25: early agressif | R25: taupe-du-recrutement.png | S25: young candidate sprinting a fitness test among other recruits in a bright training hall, all straining except him, effortless, eyes sliding sideways toward the viewer, one thin red thread bracelet, harsh white light, league of legends splash art, highly detailed, dynamic composition, cinematic lighting --no fantasy armor, text, watermark
A26: K03 | B26: executant-de-nuit | C26: À générer | D26: KAIROS | E26: Standard | F26: Traveler | G26: 2 | O26: Non | P26: — | Q26: trade | R26: executant-de-nuit.png | S26: operative in a stolen matte black exosuit dropping from a ceiling vent into a server aisle, coat flaring, red miscalibrated seams sputtering, cool blue server glow below him, league of legends splash art, highly detailed, dynamic composition, cinematic lighting --no fantasy armor, text, watermark
A27: K04 | B27: guetteur-du-moment | C27: À générer | D27: KAIROS | E27: Standard | F27: Traveler | G27: 3 | O27: Non | P27: — | Q27: punisher anti-Synchro | R27: guetteur-du-moment.png | S27: patient watcher in dark civilian clothes sitting on the roof of a ferris wheel cabin at dusk over tokyo bay, binoculars resting on his knee, wind in his coat, the fairground lights violet and gold below, one red beacon blinking far across the water, league of legends splash art, highly detailed, cinematic lighting --no fantasy armor, text, watermark
A28: K05 | B28: porteur-de-cell-vole | C28: Forgée | D28: KAIROS | E28: Standard | F28: Traveler | G28: 3 | H28: 3 | I28: 2 | J28: CELL volé · sans registre | K28: Célérité. | N28: Le suit grésille. Il s'en fout. | O28: Non | P28: — | Q28: agressif | R28: porteur-de-cell-vole.png | S28: kairos fighter in a mismatched bolted exosuit charging straight at the viewer down a parking ramp, sparks bursting from misfiring red calf conduits, sodium lights streaking overhead, league of legends splash art, highly detailed, dynamic composition, cinematic lighting --no fantasy armor, text, watermark
A29: K06 | B29: nettoyeuse | C29: À générer | D29: KAIROS | E29: Standard | F29: Traveler | G29: 4 | O29: Non | P29: — | Q29: dégâts ciblés | R29: nettoyeuse.png | S29: cold professional woman in a tailored coat walking away from a hotel entrance through light rain, steel case in hand, neon reds and cyans smearing in the wet street around her unhurried stride, league of legends splash art, highly detailed, cinematic lighting --no fantasy armor, blood, text, watermark
A30: K07 | B30: cadre-corrompu | C30: À générer | D30: KAIROS | E30: Standard | F30: Traveler | G30: 5 | O30: Non | P30: — | Q30: milieu | R30: cadre-corrompu.png | S30: executive signing documents at a boardroom table in golden hour light high above tokyo, his fountain pen scratching, a faint red emergency glow from the city reflected in the glass behind him, league of legends splash art, highly detailed, cinematic lighting --no fantasy armor, text, watermark
A31: K08 | B31: chantage | C31: À générer | D31: KAIROS | E31: Standard | F31: Protocole | G31: 1 | O31: Non | P31: — | Q31: cantrip info | R31: chantage.png | S31: close-up of a gloved hand passing a red-sealed dossier between seats of a moving maglev train, countryside smearing past the window in morning light, the other hand hesitating, league of legends splash art, highly detailed, cinematic lighting --no fantasy magic, text, watermark
A32: K09 | B32: sabotage-de-plateforme | C32: À générer | D32: KAIROS | E32: Standard | F32: Protocole | G32: 3 | O32: Non | P32: — | Q32: removal | R32: sabotage-de-plateforme.png | S32: silhouette walking calmly toward the viewer as a transfer platform erupts in blue sparks and dying light behind, red strobes sweeping the smoke, shards raining, league of legends splash art, highly detailed, dynamic composition, cinematic lighting --no explosion fireball, text, watermark
A33: K10 | B33: brouilleuse | C33: À générer | D33: KAIROS | E33: Rare | F33: Traveler | G33: 2 | O33: Non | P33: — | Q33: anti-Synchro | R33: brouilleuse.png | S33: female kairos operative crouched on the roof of a speeding maglev at night deploying a red pulse emitter, the interference wave rippling backward along the train as blue window lights die car by car, wind tearing at her coat, league of legends splash art, highly detailed, dynamic composition, cinematic lighting --no fantasy armor, text, watermark
A34: K11 | B34: duelliste-cell-tempest | C34: À générer | D34: KAIROS | E34: Rare | F34: Traveler | G34: 3 | O34: Non | P34: — | Q34: tempo | R34: duelliste-cell-tempest.png | S34: lean duelist in a stolen matte black exosuit lunging across a rain-flooded intersection at night, white-blue arc light trailing his gauntlet, red capacitor seams blazing down his spine, neon reflections shattering under his splash, league of legends splash art, highly detailed, dynamic composition, cinematic lighting --no fantasy armor, lightning storm, text, watermark
A35: K12 | B35: recruteur-double | C35: À générer | D35: KAIROS | E35: Rare | F35: Traveler | G35: 4 | O35: Non | P35: — | Q35: valeur / info | R35: recruteur-double.png | S35: charming recruiter guiding a nervous candidate down a bright corridor, arm around his shoulder, practiced warm smile, a red pen spinning in his free hand behind his back, morning light, league of legends splash art, highly detailed, cinematic lighting --no fantasy armor, text, watermark
A36: K13 | B36: colosse-de-laile-grise | C36: À générer | D36: KAIROS | E36: Rare | F36: Traveler | G36: 5 | O36: Non | P36: Aile Grise | Q36: menace | R36: colosse-de-laile-grise.png | S36: huge enforcer in a reinforced matte black exosuit shouldering through a concrete wall, rebar bending around him, dust exploding into shafts of basement sunlight, red compression bands glowing on his knuckles, league of legends splash art, highly detailed, dynamic composition, cinematic lighting --no fantasy armor, hulk, giant robot, text, watermark
A37: K14 | B37: brouillage | C37: À générer | D37: KAIROS | E37: Rare | F37: Protocole | G37: 2 | O37: Non | P37: — | Q37: anti-Synchro | R37: brouillage.png | S37: a traveler stumbling mid-sprint as his blue suit seams shatter into static, a translucent red wave passing through the frame, his momentum carrying him toward the ground, dusk street, league of legends splash art, highly detailed, dynamic composition, cinematic lighting --no fantasy magic, text, watermark
A38: K15 | B38: extraction-forcee | C38: À générer | D38: KAIROS | E38: Rare | F38: Protocole | G38: 4 | O38: Non | P38: — | Q38: removal lourd | R38: extraction-forcee.png | S38: man yanked backward off his feet into a tear of red-black static above a sunlit historical market street, fruit scattering from a knocked stall, bystanders frozen unaware, warm bronze daylight against the cold red tear, league of legends splash art, highly detailed, dynamic composition, cinematic lighting --no gore, text, watermark
A39: K16 | B39: pilleuse-depoques | C39: À générer | D39: KAIROS | E39: Épique | F39: Traveler | G39: 4 | O39: Non | P39: zones aveugles | Q39: voleur | R39: pilleuse-depoques.png | S39: female kairos agent sprinting out of a bronze fog battlefield clutching a red-lit relic case, mud kicking from her boots, ghostly still silhouettes of the era watching motionless from the mist behind her, league of legends splash art, highly detailed, dynamic composition, cinematic lighting --no fantasy armor, gore, text, watermark
A40: K17 | B40: interrogateur-du-drft | C40: À générer | D40: KAIROS | E40: Épique | F40: Traveler | G40: 5 | O40: Non | P40: — | Q40: contrôle | R40: interrogateur-du-drft.png | S40: interrogator in an immaculate dark uniform circling an empty steel chair in a blinding white room, one gloved hand trailing along its back, his long shadow sweeping the floor, a single red recording light, league of legends splash art, highly detailed, cinematic lighting --no fantasy armor, text, watermark
...

Sheet Synthèse
A1: SET 01 — ZONES AVEUGLES · synthèse de production
A3: Cartes forgées | B3: =COUNTIF('SET 01'!C2:C61,"Forgée")
A4: À générer | B4: =COUNTIF('SET 01'!C2:C61,"À générer")
A5: Progression | B5: =B3/60
A7: Faction \ Rareté | B7: Standard | C7: Rare | D7: Épique | E7: Légendaire | F7: Prismatique | G7: Total
A8: RIKKEN | B8: =COUNTIFS('SET 01'!D2:D61,"RIKKEN",'SET 01'!E2:E61,"Standard") | C8: =COUNTIFS('SET 01'!D2:D61,"RIKKEN",'SET 01'!E2:E61,"Rare") | D8: =COUNTIFS('SET 01'!D2:D61,"RIKKEN",'SET 01'!E2:E61,"Épique") | E8: =COUNTIFS('SET 01'!D2:D61,"RIKKEN",'SET 01'!E2:E61,"Légendaire") | F8: =COUNTIFS('SET 01'!D2:D61,"RIKKEN",'SET 01'!E2:E61,"Prismatique") | G8: =SUM(B8:F8)
A9: KAIROS | B9: =COUNTIFS('SET 01'!D2:D61,"KAIROS",'SET 01'!E2:E61,"Standard") | C9: =COUNTIFS('SET 01'!D2:D61,"KAIROS",'SET 01'!E2:E61,"Rare") | D9: =COUNTIFS('SET 01'!D2:D61,"KAIROS",'SET 01'!E2:E61,"Épique") | E9: =COUNTIFS('SET 01'!D2:D61,"KAIROS",'SET 01'!E2:E61,"Légendaire") | F9: =COUNTIFS('SET 01'!D2:D61,"KAIROS",'SET 01'!E2:E61,"Prismatique") | G9: =SUM(B9:F9)
A10: Les Époques | B10: =COUNTIFS('SET 01'!D2:D61,"Les Époques",'SET 01'!E2:E61,"Standard") | C10: =COUNTIFS('SET 01'!D2:D61,"Les Époques",'SET 01'!E2:E61,"Rare") | D10: =COUNTIFS('SET 01'!D2:D61,"Les Époques",'SET 01'!E2:E61,"Épique") | E10: =COUNTIFS('SET 01'!D2:D61,"Les Époques",'SET 01'!E2:E61,"Légendaire") | F10: =COUNTIFS('SET 01'!D2:D61,"Les Époques",'SET 01'!E2:E61,"Prismatique") | G10: =SUM(B10:F10)
A11: Total | B11: =SUM(B8:B10) | C11: =SUM(C8:C10) | D11: =SUM(D8:D10) | E11: =SUM(E8:E10) | F11: =SUM(F8:F10) | G11: =SUM(G8:G10)
